DEBUG:root:Starting Firebase initialization...
DEBUG:root:Using credentials file at: /Users/naveed/HomeRun/backend/credentials.json
DEBUG:root:Firebase initialized successfully!
DEBUG:root:Firestore database connection established!
DEBUG:google.auth.transport.requests:Making request: POST https://oauth2.googleapis.com/token
ERROR:grpc._plugin_wrapping:AuthMetadataPluginCallback "<google.auth.transport.grpc.AuthMetadataPlugin object at 0x7fac38e005b0>" raised exception!
Traceback (most recent call last):
  File "/Users/naveed/opt/anaconda3/lib/python3.9/site-packages/grpc/_plugin_wrapping.py", line 105, in __call__
    self._metadata_plugin(
  File "/Users/naveed/opt/anaconda3/lib/python3.9/site-packages/google/auth/transport/grpc.py", line 95, in __call__
    callback(self._get_authorization_headers(context), None)
  File "/Users/naveed/opt/anaconda3/lib/python3.9/site-packages/google/auth/transport/grpc.py", line 81, in _get_authorization_headers
    self._credentials.before_request(
  File "/Users/naveed/opt/anaconda3/lib/python3.9/site-packages/google/auth/credentials.py", line 230, in before_request
    self._blocking_refresh(request)
  File "/Users/naveed/opt/anaconda3/lib/python3.9/site-packages/google/auth/credentials.py", line 193, in _blocking_refresh
    self.refresh(request)
  File "/Users/naveed/opt/anaconda3/lib/python3.9/site-packages/google/oauth2/service_account.py", line 445, in refresh
    access_token, expiry, _ = _client.jwt_grant(
  File "/Users/naveed/opt/anaconda3/lib/python3.9/site-packages/google/oauth2/_client.py", line 308, in jwt_grant
    response_data = _token_endpoint_request(
  File "/Users/naveed/opt/anaconda3/lib/python3.9/site-packages/google/oauth2/_client.py", line 279, in _token_endpoint_request
    _handle_error_response(response_data, retryable_error)
  File "/Users/naveed/opt/anaconda3/lib/python3.9/site-packages/google/oauth2/_client.py", line 72, in _handle_error_response
    raise exceptions.RefreshError(
google.auth.exceptions.RefreshError: ('invalid_grant: Invalid JWT Signature.', {'error': 'invalid_grant', 'error_description': 'Invalid JWT Signature.'})
DEBUG:google.api_core.retry:Retrying due to 503 Getting metadata from plugin failed with error: ('invalid_grant: Invalid JWT Signature.', {'error': 'invalid_grant', 'error_description': 'Invalid JWT Signature.'}), sleeping 0.1s ...
DEBUG:google.auth.transport.requests:Making request: POST https://oauth2.googleapis.com/token
ERROR:grpc._plugin_wrapping:AuthMetadataPluginCallback "<google.auth.transport.grpc.AuthMetadataPlugin object at 0x7fac38e005b0>" raised exception!
Traceback (most recent call last):
  File "/Users/naveed/opt/anaconda3/lib/python3.9/site-packages/grpc/_plugin_wrapping.py", line 105, in __call__
    self._metadata_plugin(
  File "/Users/naveed/opt/anaconda3/lib/python3.9/site-packages/google/auth/transport/grpc.py", line 95, in __call__
    callback(self._get_authorization_headers(context), None)
  File "/Users/naveed/opt/anaconda3/lib/python3.9/site-packages/google/auth/transport/grpc.py", line 81, in _get_authorization_headers
    self._credentials.before_request(
  File "/Users/naveed/opt/anaconda3/lib/python3.9/site-packages/google/auth/credentials.py", line 230, in before_request
    self._blocking_refresh(request)
  File "/Users/naveed/opt/anaconda3/lib/python3.9/site-packages/google/auth/credentials.py", line 193, in _blocking_refresh
    self.refresh(request)
  File "/Users/naveed/opt/anaconda3/lib/python3.9/site-packages/google/oauth2/service_account.py", line 445, in refresh
    access_token, expiry, _ = _client.jwt_grant(
  File "/Users/naveed/opt/anaconda3/lib/python3.9/site-packages/google/oauth2/_client.py", line 308, in jwt_grant
    response_data = _token_endpoint_request(
  File "/Users/naveed/opt/anaconda3/lib/python3.9/site-packages/google/oauth2/_client.py", line 279, in _token_endpoint_request
    _handle_error_response(response_data, retryable_error)
  File "/Users/naveed/opt/anaconda3/lib/python3.9/site-packages/google/oauth2/_client.py", line 72, in _handle_error_response
    raise exceptions.RefreshError(
google.auth.exceptions.RefreshError: ('invalid_grant: Invalid JWT Signature.', {'error': 'invalid_grant', 'error_description': 'Invalid JWT Signature.'})
DEBUG:google.api_core.retry:Retrying due to 503 Getting metadata from plugin failed with error: ('invalid_grant: Invalid JWT Signature.', {'error': 'invalid_grant', 'error_description': 'Invalid JWT Signature.'}), sleeping 0.0s ...
DEBUG:google.auth.transport.requests:Making request: POST https://oauth2.googleapis.com/token
ERROR:grpc._plugin_wrapping:AuthMetadataPluginCallback "<google.auth.transport.grpc.AuthMetadataPlugin object at 0x7fac38e005b0>" raised exception!
Traceback (most recent call last):
  File "/Users/naveed/opt/anaconda3/lib/python3.9/site-packages/grpc/_plugin_wrapping.py", line 105, in __call__
    self._metadata_plugin(
  File "/Users/naveed/opt/anaconda3/lib/python3.9/site-packages/google/auth/transport/grpc.py", line 95, in __call__
    callback(self._get_authorization_headers(context), None)
  File "/Users/naveed/opt/anaconda3/lib/python3.9/site-packages/google/auth/transport/grpc.py", line 81, in _get_authorization_headers
    self._credentials.before_request(
  File "/Users/naveed/opt/anaconda3/lib/python3.9/site-packages/google/auth/credentials.py", line 230, in before_request
    self._blocking_refresh(request)
  File "/Users/naveed/opt/anaconda3/lib/python3.9/site-packages/google/auth/credentials.py", line 193, in _blocking_refresh
    self.refresh(request)
  File "/Users/naveed/opt/anaconda3/lib/python3.9/site-packages/google/oauth2/service_account.py", line 445, in refresh
    access_token, expiry, _ = _client.jwt_grant(
  File "/Users/naveed/opt/anaconda3/lib/python3.9/site-packages/google/oauth2/_client.py", line 308, in jwt_grant
    response_data = _token_endpoint_request(
  File "/Users/naveed/opt/anaconda3/lib/python3.9/site-packages/google/oauth2/_client.py", line 279, in _token_endpoint_request
    _handle_error_response(response_data, retryable_error)
  File "/Users/naveed/opt/anaconda3/lib/python3.9/site-packages/google/oauth2/_client.py", line 72, in _handle_error_response
    raise exceptions.RefreshError(
google.auth.exceptions.RefreshError: ('invalid_grant: Invalid JWT Signature.', {'error': 'invalid_grant', 'error_description': 'Invalid JWT Signature.'})
DEBUG:google.api_core.retry:Retrying due to 503 Getting metadata from plugin failed with error: ('invalid_grant: Invalid JWT Signature.', {'error': 'invalid_grant', 'error_description': 'Invalid JWT Signature.'}), sleeping 0.1s ...
DEBUG:google.auth.transport.requests:Making request: POST https://oauth2.googleapis.com/token
ERROR:grpc._plugin_wrapping:AuthMetadataPluginCallback "<google.auth.transport.grpc.AuthMetadataPlugin object at 0x7fac38e005b0>" raised exception!
Traceback (most recent call last):
  File "/Users/naveed/opt/anaconda3/lib/python3.9/site-packages/grpc/_plugin_wrapping.py", line 105, in __call__
    self._metadata_plugin(
  File "/Users/naveed/opt/anaconda3/lib/python3.9/site-packages/google/auth/transport/grpc.py", line 95, in __call__
    callback(self._get_authorization_headers(context), None)
  File "/Users/naveed/opt/anaconda3/lib/python3.9/site-packages/google/auth/transport/grpc.py", line 81, in _get_authorization_headers
    self._credentials.before_request(
  File "/Users/naveed/opt/anaconda3/lib/python3.9/site-packages/google/auth/credentials.py", line 230, in before_request
    self._blocking_refresh(request)
  File "/Users/naveed/opt/anaconda3/lib/python3.9/site-packages/google/auth/credentials.py", line 193, in _blocking_refresh
    self.refresh(request)
  File "/Users/naveed/opt/anaconda3/lib/python3.9/site-packages/google/oauth2/service_account.py", line 445, in refresh
    access_token, expiry, _ = _client.jwt_grant(
  File "/Users/naveed/opt/anaconda3/lib/python3.9/site-packages/google/oauth2/_client.py", line 308, in jwt_grant
    response_data = _token_endpoint_request(
  File "/Users/naveed/opt/anaconda3/lib/python3.9/site-packages/google/oauth2/_client.py", line 279, in _token_endpoint_request
    _handle_error_response(response_data, retryable_error)
  File "/Users/naveed/opt/anaconda3/lib/python3.9/site-packages/google/oauth2/_client.py", line 72, in _handle_error_response
    raise exceptions.RefreshError(
google.auth.exceptions.RefreshError: ('invalid_grant: Invalid JWT Signature.', {'error': 'invalid_grant', 'error_description': 'Invalid JWT Signature.'})
DEBUG:google.api_core.retry:Retrying due to 503 Getting metadata from plugin failed with error: ('invalid_grant: Invalid JWT Signature.', {'error': 'invalid_grant', 'error_description': 'Invalid JWT Signature.'}), sleeping 0.0s ...
DEBUG:google.auth.transport.requests:Making request: POST https://oauth2.googleapis.com/token
ERROR:grpc._plugin_wrapping:AuthMetadataPluginCallback "<google.auth.transport.grpc.AuthMetadataPlugin object at 0x7fac38e005b0>" raised exception!
Traceback (most recent call last):
  File "/Users/naveed/opt/anaconda3/lib/python3.9/site-packages/grpc/_plugin_wrapping.py", line 105, in __call__
    self._metadata_plugin(
  File "/Users/naveed/opt/anaconda3/lib/python3.9/site-packages/google/auth/transport/grpc.py", line 95, in __call__
    callback(self._get_authorization_headers(context), None)
  File "/Users/naveed/opt/anaconda3/lib/python3.9/site-packages/google/auth/transport/grpc.py", line 81, in _get_authorization_headers
    self._credentials.before_request(
  File "/Users/naveed/opt/anaconda3/lib/python3.9/site-packages/google/auth/credentials.py", line 230, in before_request
    self._blocking_refresh(request)
  File "/Users/naveed/opt/anaconda3/lib/python3.9/site-packages/google/auth/credentials.py", line 193, in _blocking_refresh
    self.refresh(request)
  File "/Users/naveed/opt/anaconda3/lib/python3.9/site-packages/google/oauth2/service_account.py", line 445, in refresh
    access_token, expiry, _ = _client.jwt_grant(
  File "/Users/naveed/opt/anaconda3/lib/python3.9/site-packages/google/oauth2/_client.py", line 308, in jwt_grant
    response_data = _token_endpoint_request(
  File "/Users/naveed/opt/anaconda3/lib/python3.9/site-packages/google/oauth2/_client.py", line 279, in _token_endpoint_request
    _handle_error_response(response_data, retryable_error)
  File "/Users/naveed/opt/anaconda3/lib/python3.9/site-packages/google/oauth2/_client.py", line 72, in _handle_error_response
    raise exceptions.RefreshError(
google.auth.exceptions.RefreshError: ('invalid_grant: Invalid JWT Signature.', {'error': 'invalid_grant', 'error_description': 'Invalid JWT Signature.'})
DEBUG:google.api_core.retry:Retrying due to 503 Getting metadata from plugin failed with error: ('invalid_grant: Invalid JWT Signature.', {'error': 'invalid_grant', 'error_description': 'Invalid JWT Signature.'}), sleeping 0.2s ...
DEBUG:google.auth.transport.requests:Making request: POST https://oauth2.googleapis.com/token
ERROR:grpc._plugin_wrapping:AuthMetadataPluginCallback "<google.auth.transport.grpc.AuthMetadataPlugin object at 0x7fac38e005b0>" raised exception!
Traceback (most recent call last):
  File "/Users/naveed/opt/anaconda3/lib/python3.9/site-packages/grpc/_plugin_wrapping.py", line 105, in __call__
    self._metadata_plugin(
  File "/Users/naveed/opt/anaconda3/lib/python3.9/site-packages/google/auth/transport/grpc.py", line 95, in __call__
    callback(self._get_authorization_headers(context), None)
  File "/Users/naveed/opt/anaconda3/lib/python3.9/site-packages/google/auth/transport/grpc.py", line 81, in _get_authorization_headers
    self._credentials.before_request(
  File "/Users/naveed/opt/anaconda3/lib/python3.9/site-packages/google/auth/credentials.py", line 230, in before_request
    self._blocking_refresh(request)
  File "/Users/naveed/opt/anaconda3/lib/python3.9/site-packages/google/auth/credentials.py", line 193, in _blocking_refresh
    self.refresh(request)
  File "/Users/naveed/opt/anaconda3/lib/python3.9/site-packages/google/oauth2/service_account.py", line 445, in refresh
    access_token, expiry, _ = _client.jwt_grant(
  File "/Users/naveed/opt/anaconda3/lib/python3.9/site-packages/google/oauth2/_client.py", line 308, in jwt_grant
    response_data = _token_endpoint_request(
  File "/Users/naveed/opt/anaconda3/lib/python3.9/site-packages/google/oauth2/_client.py", line 279, in _token_endpoint_request
    _handle_error_response(response_data, retryable_error)
  File "/Users/naveed/opt/anaconda3/lib/python3.9/site-packages/google/oauth2/_client.py", line 72, in _handle_error_response
    raise exceptions.RefreshError(
google.auth.exceptions.RefreshError: ('invalid_grant: Invalid JWT Signature.', {'error': 'invalid_grant', 'error_description': 'Invalid JWT Signature.'})
DEBUG:google.api_core.retry:Retrying due to 503 Getting metadata from plugin failed with error: ('invalid_grant: Invalid JWT Signature.', {'error': 'invalid_grant', 'error_description': 'Invalid JWT Signature.'}), sleeping 0.0s ...
DEBUG:google.auth.transport.requests:Making request: POST https://oauth2.googleapis.com/token
ERROR:grpc._plugin_wrapping:AuthMetadataPluginCallback "<google.auth.transport.grpc.AuthMetadataPlugin object at 0x7fac38e005b0>" raised exception!
Traceback (most recent call last):
  File "/Users/naveed/opt/anaconda3/lib/python3.9/site-packages/grpc/_plugin_wrapping.py", line 105, in __call__
    self._metadata_plugin(
  File "/Users/naveed/opt/anaconda3/lib/python3.9/site-packages/google/auth/transport/grpc.py", line 95, in __call__
    callback(self._get_authorization_headers(context), None)
  File "/Users/naveed/opt/anaconda3/lib/python3.9/site-packages/google/auth/transport/grpc.py", line 81, in _get_authorization_headers
    self._credentials.before_request(
  File "/Users/naveed/opt/anaconda3/lib/python3.9/site-packages/google/auth/credentials.py", line 230, in before_request
    self._blocking_refresh(request)
  File "/Users/naveed/opt/anaconda3/lib/python3.9/site-packages/google/auth/credentials.py", line 193, in _blocking_refresh
    self.refresh(request)
  File "/Users/naveed/opt/anaconda3/lib/python3.9/site-packages/google/oauth2/service_account.py", line 445, in refresh
    access_token, expiry, _ = _client.jwt_grant(
  File "/Users/naveed/opt/anaconda3/lib/python3.9/site-packages/google/oauth2/_client.py", line 308, in jwt_grant
    response_data = _token_endpoint_request(
  File "/Users/naveed/opt/anaconda3/lib/python3.9/site-packages/google/oauth2/_client.py", line 279, in _token_endpoint_request
    _handle_error_response(response_data, retryable_error)
  File "/Users/naveed/opt/anaconda3/lib/python3.9/site-packages/google/oauth2/_client.py", line 72, in _handle_error_response
    raise exceptions.RefreshError(
google.auth.exceptions.RefreshError: ('invalid_grant: Invalid JWT Signature.', {'error': 'invalid_grant', 'error_description': 'Invalid JWT Signature.'})
DEBUG:google.api_core.retry:Retrying due to 503 Getting metadata from plugin failed with error: ('invalid_grant: Invalid JWT Signature.', {'error': 'invalid_grant', 'error_description': 'Invalid JWT Signature.'}), sleeping 0.2s ...
DEBUG:google.auth.transport.requests:Making request: POST https://oauth2.googleapis.com/token
ERROR:grpc._plugin_wrapping:AuthMetadataPluginCallback "<google.auth.transport.grpc.AuthMetadataPlugin object at 0x7fac38e005b0>" raised exception!
Traceback (most recent call last):
  File "/Users/naveed/opt/anaconda3/lib/python3.9/site-packages/grpc/_plugin_wrapping.py", line 105, in __call__
    self._metadata_plugin(
  File "/Users/naveed/opt/anaconda3/lib/python3.9/site-packages/google/auth/transport/grpc.py", line 95, in __call__
    callback(self._get_authorization_headers(context), None)
  File "/Users/naveed/opt/anaconda3/lib/python3.9/site-packages/google/auth/transport/grpc.py", line 81, in _get_authorization_headers
    self._credentials.before_request(
  File "/Users/naveed/opt/anaconda3/lib/python3.9/site-packages/google/auth/credentials.py", line 230, in before_request
    self._blocking_refresh(request)
  File "/Users/naveed/opt/anaconda3/lib/python3.9/site-packages/google/auth/credentials.py", line 193, in _blocking_refresh
    self.refresh(request)
  File "/Users/naveed/opt/anaconda3/lib/python3.9/site-packages/google/oauth2/service_account.py", line 445, in refresh
    access_token, expiry, _ = _client.jwt_grant(
  File "/Users/naveed/opt/anaconda3/lib/python3.9/site-packages/google/oauth2/_client.py", line 308, in jwt_grant
    response_data = _token_endpoint_request(
  File "/Users/naveed/opt/anaconda3/lib/python3.9/site-packages/google/oauth2/_client.py", line 279, in _token_endpoint_request
    _handle_error_response(response_data, retryable_error)
  File "/Users/naveed/opt/anaconda3/lib/python3.9/site-packages/google/oauth2/_client.py", line 72, in _handle_error_response
    raise exceptions.RefreshError(
google.auth.exceptions.RefreshError: ('invalid_grant: Invalid JWT Signature.', {'error': 'invalid_grant', 'error_description': 'Invalid JWT Signature.'})
DEBUG:google.api_core.retry:Retrying due to 503 Getting metadata from plugin failed with error: ('invalid_grant: Invalid JWT Signature.', {'error': 'invalid_grant', 'error_description': 'Invalid JWT Signature.'}), sleeping 0.6s ...
DEBUG:google.auth.transport.requests:Making request: POST https://oauth2.googleapis.com/token
ERROR:grpc._plugin_wrapping:AuthMetadataPluginCallback "<google.auth.transport.grpc.AuthMetadataPlugin object at 0x7fac38e005b0>" raised exception!
Traceback (most recent call last):
  File "/Users/naveed/opt/anaconda3/lib/python3.9/site-packages/grpc/_plugin_wrapping.py", line 105, in __call__
    self._metadata_plugin(
  File "/Users/naveed/opt/anaconda3/lib/python3.9/site-packages/google/auth/transport/grpc.py", line 95, in __call__
    callback(self._get_authorization_headers(context), None)
  File "/Users/naveed/opt/anaconda3/lib/python3.9/site-packages/google/auth/transport/grpc.py", line 81, in _get_authorization_headers
    self._credentials.before_request(
  File "/Users/naveed/opt/anaconda3/lib/python3.9/site-packages/google/auth/credentials.py", line 230, in before_request
    self._blocking_refresh(request)
  File "/Users/naveed/opt/anaconda3/lib/python3.9/site-packages/google/auth/credentials.py", line 193, in _blocking_refresh
    self.refresh(request)
  File "/Users/naveed/opt/anaconda3/lib/python3.9/site-packages/google/oauth2/service_account.py", line 445, in refresh
    access_token, expiry, _ = _client.jwt_grant(
  File "/Users/naveed/opt/anaconda3/lib/python3.9/site-packages/google/oauth2/_client.py", line 308, in jwt_grant
    response_data = _token_endpoint_request(
  File "/Users/naveed/opt/anaconda3/lib/python3.9/site-packages/google/oauth2/_client.py", line 279, in _token_endpoint_request
    _handle_error_response(response_data, retryable_error)
  File "/Users/naveed/opt/anaconda3/lib/python3.9/site-packages/google/oauth2/_client.py", line 72, in _handle_error_response
    raise exceptions.RefreshError(
google.auth.exceptions.RefreshError: ('invalid_grant: Invalid JWT Signature.', {'error': 'invalid_grant', 'error_description': 'Invalid JWT Signature.'})
DEBUG:google.api_core.retry:Retrying due to 503 Getting metadata from plugin failed with error: ('invalid_grant: Invalid JWT Signature.', {'error': 'invalid_grant', 'error_description': 'Invalid JWT Signature.'}), sleeping 0.5s ...
DEBUG:google.auth.transport.requests:Making request: POST https://oauth2.googleapis.com/token
ERROR:grpc._plugin_wrapping:AuthMetadataPluginCallback "<google.auth.transport.grpc.AuthMetadataPlugin object at 0x7fac38e005b0>" raised exception!
Traceback (most recent call last):
  File "/Users/naveed/opt/anaconda3/lib/python3.9/site-packages/grpc/_plugin_wrapping.py", line 105, in __call__
    self._metadata_plugin(
  File "/Users/naveed/opt/anaconda3/lib/python3.9/site-packages/google/auth/transport/grpc.py", line 95, in __call__
    callback(self._get_authorization_headers(context), None)
  File "/Users/naveed/opt/anaconda3/lib/python3.9/site-packages/google/auth/transport/grpc.py", line 81, in _get_authorization_headers
    self._credentials.before_request(
  File "/Users/naveed/opt/anaconda3/lib/python3.9/site-packages/google/auth/credentials.py", line 230, in before_request
    self._blocking_refresh(request)
  File "/Users/naveed/opt/anaconda3/lib/python3.9/site-packages/google/auth/credentials.py", line 193, in _blocking_refresh
    self.refresh(request)
  File "/Users/naveed/opt/anaconda3/lib/python3.9/site-packages/google/oauth2/service_account.py", line 445, in refresh
    access_token, expiry, _ = _client.jwt_grant(
  File "/Users/naveed/opt/anaconda3/lib/python3.9/site-packages/google/oauth2/_client.py", line 308, in jwt_grant
    response_data = _token_endpoint_request(
  File "/Users/naveed/opt/anaconda3/lib/python3.9/site-packages/google/oauth2/_client.py", line 279, in _token_endpoint_request
    _handle_error_response(response_data, retryable_error)
  File "/Users/naveed/opt/anaconda3/lib/python3.9/site-packages/google/oauth2/_client.py", line 72, in _handle_error_response
    raise exceptions.RefreshError(
google.auth.exceptions.RefreshError: ('invalid_grant: Invalid JWT Signature.', {'error': 'invalid_grant', 'error_description': 'Invalid JWT Signature.'})
DEBUG:google.api_core.retry:Retrying due to 503 Getting metadata from plugin failed with error: ('invalid_grant: Invalid JWT Signature.', {'error': 'invalid_grant', 'error_description': 'Invalid JWT Signature.'}), sleeping 0.2s ...
DEBUG:google.auth.transport.requests:Making request: POST https://oauth2.googleapis.com/token
ERROR:grpc._plugin_wrapping:AuthMetadataPluginCallback "<google.auth.transport.grpc.AuthMetadataPlugin object at 0x7fac38e005b0>" raised exception!
Traceback (most recent call last):
  File "/Users/naveed/opt/anaconda3/lib/python3.9/site-packages/grpc/_plugin_wrapping.py", line 105, in __call__
    self._metadata_plugin(
  File "/Users/naveed/opt/anaconda3/lib/python3.9/site-packages/google/auth/transport/grpc.py", line 95, in __call__
    callback(self._get_authorization_headers(context), None)
  File "/Users/naveed/opt/anaconda3/lib/python3.9/site-packages/google/auth/transport/grpc.py", line 81, in _get_authorization_headers
    self._credentials.before_request(
  File "/Users/naveed/opt/anaconda3/lib/python3.9/site-packages/google/auth/credentials.py", line 230, in before_request
    self._blocking_refresh(request)
  File "/Users/naveed/opt/anaconda3/lib/python3.9/site-packages/google/auth/credentials.py", line 193, in _blocking_refresh
    self.refresh(request)
  File "/Users/naveed/opt/anaconda3/lib/python3.9/site-packages/google/oauth2/service_account.py", line 445, in refresh
    access_token, expiry, _ = _client.jwt_grant(
  File "/Users/naveed/opt/anaconda3/lib/python3.9/site-packages/google/oauth2/_client.py", line 308, in jwt_grant
    response_data = _token_endpoint_request(
  File "/Users/naveed/opt/anaconda3/lib/python3.9/site-packages/google/oauth2/_client.py", line 279, in _token_endpoint_request
    _handle_error_response(response_data, retryable_error)
  File "/Users/naveed/opt/anaconda3/lib/python3.9/site-packages/google/oauth2/_client.py", line 72, in _handle_error_response
    raise exceptions.RefreshError(
google.auth.exceptions.RefreshError: ('invalid_grant: Invalid JWT Signature.', {'error': 'invalid_grant', 'error_description': 'Invalid JWT Signature.'})
DEBUG:google.api_core.retry:Retrying due to 503 Getting metadata from plugin failed with error: ('invalid_grant: Invalid JWT Signature.', {'error': 'invalid_grant', 'error_description': 'Invalid JWT Signature.'}), sleeping 1.0s ...
DEBUG:google.auth.transport.requests:Making request: POST https://oauth2.googleapis.com/token
ERROR:grpc._plugin_wrapping:AuthMetadataPluginCallback "<google.auth.transport.grpc.AuthMetadataPlugin object at 0x7fac38e005b0>" raised exception!
Traceback (most recent call last):
  File "/Users/naveed/opt/anaconda3/lib/python3.9/site-packages/grpc/_plugin_wrapping.py", line 105, in __call__
    self._metadata_plugin(
  File "/Users/naveed/opt/anaconda3/lib/python3.9/site-packages/google/auth/transport/grpc.py", line 95, in __call__
    callback(self._get_authorization_headers(context), None)
  File "/Users/naveed/opt/anaconda3/lib/python3.9/site-packages/google/auth/transport/grpc.py", line 81, in _get_authorization_headers
    self._credentials.before_request(
  File "/Users/naveed/opt/anaconda3/lib/python3.9/site-packages/google/auth/credentials.py", line 230, in before_request
    self._blocking_refresh(request)
  File "/Users/naveed/opt/anaconda3/lib/python3.9/site-packages/google/auth/credentials.py", line 193, in _blocking_refresh
    self.refresh(request)
  File "/Users/naveed/opt/anaconda3/lib/python3.9/site-packages/google/oauth2/service_account.py", line 445, in refresh
    access_token, expiry, _ = _client.jwt_grant(
  File "/Users/naveed/opt/anaconda3/lib/python3.9/site-packages/google/oauth2/_client.py", line 308, in jwt_grant
    response_data = _token_endpoint_request(
  File "/Users/naveed/opt/anaconda3/lib/python3.9/site-packages/google/oauth2/_client.py", line 279, in _token_endpoint_request
    _handle_error_response(response_data, retryable_error)
  File "/Users/naveed/opt/anaconda3/lib/python3.9/site-packages/google/oauth2/_client.py", line 72, in _handle_error_response
    raise exceptions.RefreshError(
google.auth.exceptions.RefreshError: ('invalid_grant: Invalid JWT Signature.', {'error': 'invalid_grant', 'error_description': 'Invalid JWT Signature.'})
DEBUG:google.api_core.retry:Retrying due to 503 Getting metadata from plugin failed with error: ('invalid_grant: Invalid JWT Signature.', {'error': 'invalid_grant', 'error_description': 'Invalid JWT Signature.'}), sleeping 1.4s ...
DEBUG:google.auth.transport.requests:Making request: POST https://oauth2.googleapis.com/token
ERROR:grpc._plugin_wrapping:AuthMetadataPluginCallback "<google.auth.transport.grpc.AuthMetadataPlugin object at 0x7fac38e005b0>" raised exception!
Traceback (most recent call last):
  File "/Users/naveed/opt/anaconda3/lib/python3.9/site-packages/grpc/_plugin_wrapping.py", line 105, in __call__
    self._metadata_plugin(
  File "/Users/naveed/opt/anaconda3/lib/python3.9/site-packages/google/auth/transport/grpc.py", line 95, in __call__
    callback(self._get_authorization_headers(context), None)
  File "/Users/naveed/opt/anaconda3/lib/python3.9/site-packages/google/auth/transport/grpc.py", line 81, in _get_authorization_headers
    self._credentials.before_request(
  File "/Users/naveed/opt/anaconda3/lib/python3.9/site-packages/google/auth/credentials.py", line 230, in before_request
    self._blocking_refresh(request)
  File "/Users/naveed/opt/anaconda3/lib/python3.9/site-packages/google/auth/credentials.py", line 193, in _blocking_refresh
    self.refresh(request)
  File "/Users/naveed/opt/anaconda3/lib/python3.9/site-packages/google/oauth2/service_account.py", line 445, in refresh
    access_token, expiry, _ = _client.jwt_grant(
  File "/Users/naveed/opt/anaconda3/lib/python3.9/site-packages/google/oauth2/_client.py", line 308, in jwt_grant
    response_data = _token_endpoint_request(
  File "/Users/naveed/opt/anaconda3/lib/python3.9/site-packages/google/oauth2/_client.py", line 279, in _token_endpoint_request
    _handle_error_response(response_data, retryable_error)
  File "/Users/naveed/opt/anaconda3/lib/python3.9/site-packages/google/oauth2/_client.py", line 72, in _handle_error_response
    raise exceptions.RefreshError(
google.auth.exceptions.RefreshError: ('invalid_grant: Invalid JWT Signature.', {'error': 'invalid_grant', 'error_description': 'Invalid JWT Signature.'})
DEBUG:google.api_core.retry:Retrying due to 503 Getting metadata from plugin failed with error: ('invalid_grant: Invalid JWT Signature.', {'error': 'invalid_grant', 'error_description': 'Invalid JWT Signature.'}), sleeping 2.0s ...
DEBUG:google.auth.transport.requests:Making request: POST https://oauth2.googleapis.com/token
ERROR:grpc._plugin_wrapping:AuthMetadataPluginCallback "<google.auth.transport.grpc.AuthMetadataPlugin object at 0x7fac38e005b0>" raised exception!
Traceback (most recent call last):
  File "/Users/naveed/opt/anaconda3/lib/python3.9/site-packages/grpc/_plugin_wrapping.py", line 105, in __call__
    self._metadata_plugin(
  File "/Users/naveed/opt/anaconda3/lib/python3.9/site-packages/google/auth/transport/grpc.py", line 95, in __call__
    callback(self._get_authorization_headers(context), None)
  File "/Users/naveed/opt/anaconda3/lib/python3.9/site-packages/google/auth/transport/grpc.py", line 81, in _get_authorization_headers
    self._credentials.before_request(
  File "/Users/naveed/opt/anaconda3/lib/python3.9/site-packages/google/auth/credentials.py", line 230, in before_request
    self._blocking_refresh(request)
  File "/Users/naveed/opt/anaconda3/lib/python3.9/site-packages/google/auth/credentials.py", line 193, in _blocking_refresh
    self.refresh(request)
  File "/Users/naveed/opt/anaconda3/lib/python3.9/site-packages/google/oauth2/service_account.py", line 445, in refresh
    access_token, expiry, _ = _client.jwt_grant(
  File "/Users/naveed/opt/anaconda3/lib/python3.9/site-packages/google/oauth2/_client.py", line 308, in jwt_grant
    response_data = _token_endpoint_request(
  File "/Users/naveed/opt/anaconda3/lib/python3.9/site-packages/google/oauth2/_client.py", line 279, in _token_endpoint_request
    _handle_error_response(response_data, retryable_error)
  File "/Users/naveed/opt/anaconda3/lib/python3.9/site-packages/google/oauth2/_client.py", line 72, in _handle_error_response
    raise exceptions.RefreshError(
google.auth.exceptions.RefreshError: ('invalid_grant: Invalid JWT Signature.', {'error': 'invalid_grant', 'error_description': 'Invalid JWT Signature.'})
DEBUG:google.api_core.retry:Retrying due to 503 Getting metadata from plugin failed with error: ('invalid_grant: Invalid JWT Signature.', {'error': 'invalid_grant', 'error_description': 'Invalid JWT Signature.'}), sleeping 0.7s ...
DEBUG:google.auth.transport.requests:Making request: POST https://oauth2.googleapis.com/token
ERROR:grpc._plugin_wrapping:AuthMetadataPluginCallback "<google.auth.transport.grpc.AuthMetadataPlugin object at 0x7fac38e005b0>" raised exception!
Traceback (most recent call last):
  File "/Users/naveed/opt/anaconda3/lib/python3.9/site-packages/grpc/_plugin_wrapping.py", line 105, in __call__
    self._metadata_plugin(
  File "/Users/naveed/opt/anaconda3/lib/python3.9/site-packages/google/auth/transport/grpc.py", line 95, in __call__
    callback(self._get_authorization_headers(context), None)
  File "/Users/naveed/opt/anaconda3/lib/python3.9/site-packages/google/auth/transport/grpc.py", line 81, in _get_authorization_headers
    self._credentials.before_request(
  File "/Users/naveed/opt/anaconda3/lib/python3.9/site-packages/google/auth/credentials.py", line 230, in before_request
    self._blocking_refresh(request)
  File "/Users/naveed/opt/anaconda3/lib/python3.9/site-packages/google/auth/credentials.py", line 193, in _blocking_refresh
    self.refresh(request)
  File "/Users/naveed/opt/anaconda3/lib/python3.9/site-packages/google/oauth2/service_account.py", line 445, in refresh
    access_token, expiry, _ = _client.jwt_grant(
  File "/Users/naveed/opt/anaconda3/lib/python3.9/site-packages/google/oauth2/_client.py", line 308, in jwt_grant
    response_data = _token_endpoint_request(
  File "/Users/naveed/opt/anaconda3/lib/python3.9/site-packages/google/oauth2/_client.py", line 279, in _token_endpoint_request
    _handle_error_response(response_data, retryable_error)
  File "/Users/naveed/opt/anaconda3/lib/python3.9/site-packages/google/oauth2/_client.py", line 72, in _handle_error_response
    raise exceptions.RefreshError(
google.auth.exceptions.RefreshError: ('invalid_grant: Invalid JWT Signature.', {'error': 'invalid_grant', 'error_description': 'Invalid JWT Signature.'})
DEBUG:google.api_core.retry:Retrying due to 503 Getting metadata from plugin failed with error: ('invalid_grant: Invalid JWT Signature.', {'error': 'invalid_grant', 'error_description': 'Invalid JWT Signature.'}), sleeping 2.8s ...
DEBUG:google.auth.transport.requests:Making request: POST https://oauth2.googleapis.com/token
ERROR:grpc._plugin_wrapping:AuthMetadataPluginCallback "<google.auth.transport.grpc.AuthMetadataPlugin object at 0x7fac38e005b0>" raised exception!
Traceback (most recent call last):
  File "/Users/naveed/opt/anaconda3/lib/python3.9/site-packages/grpc/_plugin_wrapping.py", line 105, in __call__
    self._metadata_plugin(
  File "/Users/naveed/opt/anaconda3/lib/python3.9/site-packages/google/auth/transport/grpc.py", line 95, in __call__
    callback(self._get_authorization_headers(context), None)
  File "/Users/naveed/opt/anaconda3/lib/python3.9/site-packages/google/auth/transport/grpc.py", line 81, in _get_authorization_headers
    self._credentials.before_request(
  File "/Users/naveed/opt/anaconda3/lib/python3.9/site-packages/google/auth/credentials.py", line 230, in before_request
    self._blocking_refresh(request)
  File "/Users/naveed/opt/anaconda3/lib/python3.9/site-packages/google/auth/credentials.py", line 193, in _blocking_refresh
    self.refresh(request)
  File "/Users/naveed/opt/anaconda3/lib/python3.9/site-packages/google/oauth2/service_account.py", line 445, in refresh
    access_token, expiry, _ = _client.jwt_grant(
  File "/Users/naveed/opt/anaconda3/lib/python3.9/site-packages/google/oauth2/_client.py", line 308, in jwt_grant
    response_data = _token_endpoint_request(
  File "/Users/naveed/opt/anaconda3/lib/python3.9/site-packages/google/oauth2/_client.py", line 279, in _token_endpoint_request
    _handle_error_response(response_data, retryable_error)
  File "/Users/naveed/opt/anaconda3/lib/python3.9/site-packages/google/oauth2/_client.py", line 72, in _handle_error_response
    raise exceptions.RefreshError(
google.auth.exceptions.RefreshError: ('invalid_grant: Invalid JWT Signature.', {'error': 'invalid_grant', 'error_description': 'Invalid JWT Signature.'})
DEBUG:google.api_core.retry:Retrying due to 503 Getting metadata from plugin failed with error: ('invalid_grant: Invalid JWT Signature.', {'error': 'invalid_grant', 'error_description': 'Invalid JWT Signature.'}), sleeping 5.0s ...
DEBUG:google.auth.transport.requests:Making request: POST https://oauth2.googleapis.com/token
ERROR:grpc._plugin_wrapping:AuthMetadataPluginCallback "<google.auth.transport.grpc.AuthMetadataPlugin object at 0x7fac38e005b0>" raised exception!
Traceback (most recent call last):
  File "/Users/naveed/opt/anaconda3/lib/python3.9/site-packages/grpc/_plugin_wrapping.py", line 105, in __call__
    self._metadata_plugin(
  File "/Users/naveed/opt/anaconda3/lib/python3.9/site-packages/google/auth/transport/grpc.py", line 95, in __call__
    callback(self._get_authorization_headers(context), None)
  File "/Users/naveed/opt/anaconda3/lib/python3.9/site-packages/google/auth/transport/grpc.py", line 81, in _get_authorization_headers
    self._credentials.before_request(
  File "/Users/naveed/opt/anaconda3/lib/python3.9/site-packages/google/auth/credentials.py", line 230, in before_request
    self._blocking_refresh(request)
  File "/Users/naveed/opt/anaconda3/lib/python3.9/site-packages/google/auth/credentials.py", line 193, in _blocking_refresh
    self.refresh(request)
  File "/Users/naveed/opt/anaconda3/lib/python3.9/site-packages/google/oauth2/service_account.py", line 445, in refresh
    access_token, expiry, _ = _client.jwt_grant(
  File "/Users/naveed/opt/anaconda3/lib/python3.9/site-packages/google/oauth2/_client.py", line 308, in jwt_grant
    response_data = _token_endpoint_request(
  File "/Users/naveed/opt/anaconda3/lib/python3.9/site-packages/google/oauth2/_client.py", line 279, in _token_endpoint_request
    _handle_error_response(response_data, retryable_error)
  File "/Users/naveed/opt/anaconda3/lib/python3.9/site-packages/google/oauth2/_client.py", line 72, in _handle_error_response
    raise exceptions.RefreshError(
google.auth.exceptions.RefreshError: ('invalid_grant: Invalid JWT Signature.', {'error': 'invalid_grant', 'error_description': 'Invalid JWT Signature.'})
DEBUG:google.api_core.retry:Retrying due to 503 Getting metadata from plugin failed with error: ('invalid_grant: Invalid JWT Signature.', {'error': 'invalid_grant', 'error_description': 'Invalid JWT Signature.'}), sleeping 1.9s ...
DEBUG:google.auth.transport.requests:Making request: POST https://oauth2.googleapis.com/token
ERROR:grpc._plugin_wrapping:AuthMetadataPluginCallback "<google.auth.transport.grpc.AuthMetadataPlugin object at 0x7fac38e005b0>" raised exception!
Traceback (most recent call last):
  File "/Users/naveed/opt/anaconda3/lib/python3.9/site-packages/grpc/_plugin_wrapping.py", line 105, in __call__
    self._metadata_plugin(
  File "/Users/naveed/opt/anaconda3/lib/python3.9/site-packages/google/auth/transport/grpc.py", line 95, in __call__
    callback(self._get_authorization_headers(context), None)
  File "/Users/naveed/opt/anaconda3/lib/python3.9/site-packages/google/auth/transport/grpc.py", line 81, in _get_authorization_headers
    self._credentials.before_request(
  File "/Users/naveed/opt/anaconda3/lib/python3.9/site-packages/google/auth/credentials.py", line 230, in before_request
    self._blocking_refresh(request)
  File "/Users/naveed/opt/anaconda3/lib/python3.9/site-packages/google/auth/credentials.py", line 193, in _blocking_refresh
    self.refresh(request)
  File "/Users/naveed/opt/anaconda3/lib/python3.9/site-packages/google/oauth2/service_account.py", line 445, in refresh
    access_token, expiry, _ = _client.jwt_grant(
  File "/Users/naveed/opt/anaconda3/lib/python3.9/site-packages/google/oauth2/_client.py", line 308, in jwt_grant
    response_data = _token_endpoint_request(
  File "/Users/naveed/opt/anaconda3/lib/python3.9/site-packages/google/oauth2/_client.py", line 279, in _token_endpoint_request
    _handle_error_response(response_data, retryable_error)
  File "/Users/naveed/opt/anaconda3/lib/python3.9/site-packages/google/oauth2/_client.py", line 72, in _handle_error_response
    raise exceptions.RefreshError(
google.auth.exceptions.RefreshError: ('invalid_grant: Invalid JWT Signature.', {'error': 'invalid_grant', 'error_description': 'Invalid JWT Signature.'})
DEBUG:google.api_core.retry:Retrying due to 503 Getting metadata from plugin failed with error: ('invalid_grant: Invalid JWT Signature.', {'error': 'invalid_grant', 'error_description': 'Invalid JWT Signature.'}), sleeping 3.8s ...
DEBUG:google.auth.transport.requests:Making request: POST https://oauth2.googleapis.com/token
ERROR:grpc._plugin_wrapping:AuthMetadataPluginCallback "<google.auth.transport.grpc.AuthMetadataPlugin object at 0x7fac38e005b0>" raised exception!
Traceback (most recent call last):
  File "/Users/naveed/opt/anaconda3/lib/python3.9/site-packages/grpc/_plugin_wrapping.py", line 105, in __call__
    self._metadata_plugin(
  File "/Users/naveed/opt/anaconda3/lib/python3.9/site-packages/google/auth/transport/grpc.py", line 95, in __call__
    callback(self._get_authorization_headers(context), None)
  File "/Users/naveed/opt/anaconda3/lib/python3.9/site-packages/google/auth/transport/grpc.py", line 81, in _get_authorization_headers
    self._credentials.before_request(
  File "/Users/naveed/opt/anaconda3/lib/python3.9/site-packages/google/auth/credentials.py", line 230, in before_request
    self._blocking_refresh(request)
  File "/Users/naveed/opt/anaconda3/lib/python3.9/site-packages/google/auth/credentials.py", line 193, in _blocking_refresh
    self.refresh(request)
  File "/Users/naveed/opt/anaconda3/lib/python3.9/site-packages/google/oauth2/service_account.py", line 445, in refresh
    access_token, expiry, _ = _client.jwt_grant(
  File "/Users/naveed/opt/anaconda3/lib/python3.9/site-packages/google/oauth2/_client.py", line 308, in jwt_grant
    response_data = _token_endpoint_request(
  File "/Users/naveed/opt/anaconda3/lib/python3.9/site-packages/google/oauth2/_client.py", line 279, in _token_endpoint_request
    _handle_error_response(response_data, retryable_error)
  File "/Users/naveed/opt/anaconda3/lib/python3.9/site-packages/google/oauth2/_client.py", line 72, in _handle_error_response
    raise exceptions.RefreshError(
google.auth.exceptions.RefreshError: ('invalid_grant: Invalid JWT Signature.', {'error': 'invalid_grant', 'error_description': 'Invalid JWT Signature.'})
DEBUG:google.api_core.retry:Retrying due to 503 Getting metadata from plugin failed with error: ('invalid_grant: Invalid JWT Signature.', {'error': 'invalid_grant', 'error_description': 'Invalid JWT Signature.'}), sleeping 5.0s ...
DEBUG:google.auth.transport.requests:Making request: POST https://oauth2.googleapis.com/token
ERROR:grpc._plugin_wrapping:AuthMetadataPluginCallback "<google.auth.transport.grpc.AuthMetadataPlugin object at 0x7fac38e005b0>" raised exception!
Traceback (most recent call last):
  File "/Users/naveed/opt/anaconda3/lib/python3.9/site-packages/grpc/_plugin_wrapping.py", line 105, in __call__
    self._metadata_plugin(
  File "/Users/naveed/opt/anaconda3/lib/python3.9/site-packages/google/auth/transport/grpc.py", line 95, in __call__
    callback(self._get_authorization_headers(context), None)
  File "/Users/naveed/opt/anaconda3/lib/python3.9/site-packages/google/auth/transport/grpc.py", line 81, in _get_authorization_headers
    self._credentials.before_request(
  File "/Users/naveed/opt/anaconda3/lib/python3.9/site-packages/google/auth/credentials.py", line 230, in before_request
    self._blocking_refresh(request)
  File "/Users/naveed/opt/anaconda3/lib/python3.9/site-packages/google/auth/credentials.py", line 193, in _blocking_refresh
    self.refresh(request)
  File "/Users/naveed/opt/anaconda3/lib/python3.9/site-packages/google/oauth2/service_account.py", line 445, in refresh
    access_token, expiry, _ = _client.jwt_grant(
  File "/Users/naveed/opt/anaconda3/lib/python3.9/site-packages/google/oauth2/_client.py", line 308, in jwt_grant
    response_data = _token_endpoint_request(
  File "/Users/naveed/opt/anaconda3/lib/python3.9/site-packages/google/oauth2/_client.py", line 279, in _token_endpoint_request
    _handle_error_response(response_data, retryable_error)
  File "/Users/naveed/opt/anaconda3/lib/python3.9/site-packages/google/oauth2/_client.py", line 72, in _handle_error_response
    raise exceptions.RefreshError(
google.auth.exceptions.RefreshError: ('invalid_grant: Invalid JWT Signature.', {'error': 'invalid_grant', 'error_description': 'Invalid JWT Signature.'})
DEBUG:google.api_core.retry:Retrying due to 503 Getting metadata from plugin failed with error: ('invalid_grant: Invalid JWT Signature.', {'error': 'invalid_grant', 'error_description': 'Invalid JWT Signature.'}), sleeping 2.5s ...
DEBUG:google.auth.transport.requests:Making request: POST https://oauth2.googleapis.com/token
ERROR:grpc._plugin_wrapping:AuthMetadataPluginCallback "<google.auth.transport.grpc.AuthMetadataPlugin object at 0x7fac38e005b0>" raised exception!
Traceback (most recent call last):
  File "/Users/naveed/opt/anaconda3/lib/python3.9/site-packages/grpc/_plugin_wrapping.py", line 105, in __call__
    self._metadata_plugin(
  File "/Users/naveed/opt/anaconda3/lib/python3.9/site-packages/google/auth/transport/grpc.py", line 95, in __call__
    callback(self._get_authorization_headers(context), None)
  File "/Users/naveed/opt/anaconda3/lib/python3.9/site-packages/google/auth/transport/grpc.py", line 81, in _get_authorization_headers
    self._credentials.before_request(
  File "/Users/naveed/opt/anaconda3/lib/python3.9/site-packages/google/auth/credentials.py", line 230, in before_request
    self._blocking_refresh(request)
  File "/Users/naveed/opt/anaconda3/lib/python3.9/site-packages/google/auth/credentials.py", line 193, in _blocking_refresh
    self.refresh(request)
  File "/Users/naveed/opt/anaconda3/lib/python3.9/site-packages/google/oauth2/service_account.py", line 445, in refresh
    access_token, expiry, _ = _client.jwt_grant(
  File "/Users/naveed/opt/anaconda3/lib/python3.9/site-packages/google/oauth2/_client.py", line 308, in jwt_grant
    response_data = _token_endpoint_request(
  File "/Users/naveed/opt/anaconda3/lib/python3.9/site-packages/google/oauth2/_client.py", line 279, in _token_endpoint_request
    _handle_error_response(response_data, retryable_error)
  File "/Users/naveed/opt/anaconda3/lib/python3.9/site-packages/google/oauth2/_client.py", line 72, in _handle_error_response
    raise exceptions.RefreshError(
google.auth.exceptions.RefreshError: ('invalid_grant: Invalid JWT Signature.', {'error': 'invalid_grant', 'error_description': 'Invalid JWT Signature.'})
DEBUG:google.api_core.retry:Retrying due to 503 Getting metadata from plugin failed with error: ('invalid_grant: Invalid JWT Signature.', {'error': 'invalid_grant', 'error_description': 'Invalid JWT Signature.'}), sleeping 3.7s ...
DEBUG:google.auth.transport.requests:Making request: POST https://oauth2.googleapis.com/token
ERROR:grpc._plugin_wrapping:AuthMetadataPluginCallback "<google.auth.transport.grpc.AuthMetadataPlugin object at 0x7fac38e005b0>" raised exception!
Traceback (most recent call last):
  File "/Users/naveed/opt/anaconda3/lib/python3.9/site-packages/grpc/_plugin_wrapping.py", line 105, in __call__
    self._metadata_plugin(
  File "/Users/naveed/opt/anaconda3/lib/python3.9/site-packages/google/auth/transport/grpc.py", line 95, in __call__
    callback(self._get_authorization_headers(context), None)
  File "/Users/naveed/opt/anaconda3/lib/python3.9/site-packages/google/auth/transport/grpc.py", line 81, in _get_authorization_headers
    self._credentials.before_request(
  File "/Users/naveed/opt/anaconda3/lib/python3.9/site-packages/google/auth/credentials.py", line 230, in before_request
    self._blocking_refresh(request)
  File "/Users/naveed/opt/anaconda3/lib/python3.9/site-packages/google/auth/credentials.py", line 193, in _blocking_refresh
    self.refresh(request)
  File "/Users/naveed/opt/anaconda3/lib/python3.9/site-packages/google/oauth2/service_account.py", line 445, in refresh
    access_token, expiry, _ = _client.jwt_grant(
  File "/Users/naveed/opt/anaconda3/lib/python3.9/site-packages/google/oauth2/_client.py", line 308, in jwt_grant
    response_data = _token_endpoint_request(
  File "/Users/naveed/opt/anaconda3/lib/python3.9/site-packages/google/oauth2/_client.py", line 279, in _token_endpoint_request
    _handle_error_response(response_data, retryable_error)
  File "/Users/naveed/opt/anaconda3/lib/python3.9/site-packages/google/oauth2/_client.py", line 72, in _handle_error_response
    raise exceptions.RefreshError(
google.auth.exceptions.RefreshError: ('invalid_grant: Invalid JWT Signature.', {'error': 'invalid_grant', 'error_description': 'Invalid JWT Signature.'})
DEBUG:google.api_core.retry:Retrying due to 503 Getting metadata from plugin failed with error: ('invalid_grant: Invalid JWT Signature.', {'error': 'invalid_grant', 'error_description': 'Invalid JWT Signature.'}), sleeping 16.4s ...
DEBUG:google.auth.transport.requests:Making request: POST https://oauth2.googleapis.com/token
ERROR:grpc._plugin_wrapping:AuthMetadataPluginCallback "<google.auth.transport.grpc.AuthMetadataPlugin object at 0x7fac38e005b0>" raised exception!
Traceback (most recent call last):
  File "/Users/naveed/opt/anaconda3/lib/python3.9/site-packages/grpc/_plugin_wrapping.py", line 105, in __call__
    self._metadata_plugin(
  File "/Users/naveed/opt/anaconda3/lib/python3.9/site-packages/google/auth/transport/grpc.py", line 95, in __call__
    callback(self._get_authorization_headers(context), None)
  File "/Users/naveed/opt/anaconda3/lib/python3.9/site-packages/google/auth/transport/grpc.py", line 81, in _get_authorization_headers
    self._credentials.before_request(
  File "/Users/naveed/opt/anaconda3/lib/python3.9/site-packages/google/auth/credentials.py", line 230, in before_request
    self._blocking_refresh(request)
  File "/Users/naveed/opt/anaconda3/lib/python3.9/site-packages/google/auth/credentials.py", line 193, in _blocking_refresh
    self.refresh(request)
  File "/Users/naveed/opt/anaconda3/lib/python3.9/site-packages/google/oauth2/service_account.py", line 445, in refresh
    access_token, expiry, _ = _client.jwt_grant(
  File "/Users/naveed/opt/anaconda3/lib/python3.9/site-packages/google/oauth2/_client.py", line 308, in jwt_grant
    response_data = _token_endpoint_request(
  File "/Users/naveed/opt/anaconda3/lib/python3.9/site-packages/google/oauth2/_client.py", line 279, in _token_endpoint_request
    _handle_error_response(response_data, retryable_error)
  File "/Users/naveed/opt/anaconda3/lib/python3.9/site-packages/google/oauth2/_client.py", line 72, in _handle_error_response
    raise exceptions.RefreshError(
google.auth.exceptions.RefreshError: ('invalid_grant: Invalid JWT Signature.', {'error': 'invalid_grant', 'error_description': 'Invalid JWT Signature.'})
Plaid API successfully initialized!
✅ Firebase connection successful!
Traceback (most recent call last):
  File "/Users/naveed/opt/anaconda3/lib/python3.9/site-packages/google/api_core/grpc_helpers.py", line 76, in error_remapped_callable
    return callable_(*args, **kwargs)
  File "/Users/naveed/opt/anaconda3/lib/python3.9/site-packages/grpc/_channel.py", line 1181, in __call__
    return _end_unary_response_blocking(state, call, False, None)
  File "/Users/naveed/opt/anaconda3/lib/python3.9/site-packages/grpc/_channel.py", line 1006, in _end_unary_response_blocking
    raise _InactiveRpcError(state)  # pytype: disable=not-instantiable
grpc._channel._InactiveRpcError: <_InactiveRpcError of RPC that terminated with:
	status = StatusCode.UNAVAILABLE
	details = "Getting metadata from plugin failed with error: ('invalid_grant: Invalid JWT Signature.', {'error': 'invalid_grant', 'error_description': 'Invalid JWT Signature.'})"
	debug_error_string = "UNKNOWN:Error received from peer  {grpc_message:"Getting metadata from plugin failed with error: (\'invalid_grant: Invalid JWT Signature.\', {\'error\': \'invalid_grant\', \'error_description\': \'Invalid JWT Signature.\'})", grpc_status:14, created_time:"2025-02-15T20:41:03.579214-07:00"}"
>

The above exception was the direct cause of the following exception:

Traceback (most recent call last):
  File "/Users/naveed/opt/anaconda3/lib/python3.9/site-packages/google/api_core/retry/retry_unary.py", line 144, in retry_target
    result = target()
  File "/Users/naveed/opt/anaconda3/lib/python3.9/site-packages/google/api_core/timeout.py", line 120, in func_with_timeout
    return func(*args, **kwargs)
  File "/Users/naveed/opt/anaconda3/lib/python3.9/site-packages/google/api_core/grpc_helpers.py", line 78, in error_remapped_callable
    raise exceptions.from_grpc_error(exc) from exc
google.api_core.exceptions.ServiceUnavailable: 503 Getting metadata from plugin failed with error: ('invalid_grant: Invalid JWT Signature.', {'error': 'invalid_grant', 'error_description': 'Invalid JWT Signature.'})

The above exception was the direct cause of the following exception:

Traceback (most recent call last):
  File "/Users/naveed/HomeRun/backend/main.py", line 77, in <module>
    doc_ref.set({"message": "Firebase connected successfully!"})
  File "/Users/naveed/opt/anaconda3/lib/python3.9/site-packages/google/cloud/firestore_v1/document.py", line 167, in set
    write_results = batch.commit(**kwargs)
  File "/Users/naveed/opt/anaconda3/lib/python3.9/site-packages/google/cloud/firestore_v1/batch.py", line 61, in commit
    commit_response = self._client._firestore_api.commit(
  File "/Users/naveed/opt/anaconda3/lib/python3.9/site-packages/google/cloud/firestore_v1/services/firestore/client.py", line 1372, in commit
    response = rpc(
  File "/Users/naveed/opt/anaconda3/lib/python3.9/site-packages/google/api_core/gapic_v1/method.py", line 131, in __call__
    return wrapped_func(*args, **kwargs)
  File "/Users/naveed/opt/anaconda3/lib/python3.9/site-packages/google/api_core/retry/retry_unary.py", line 293, in retry_wrapped_func
    return retry_target(
  File "/Users/naveed/opt/anaconda3/lib/python3.9/site-packages/google/api_core/retry/retry_unary.py", line 153, in retry_target
    _retry_error_helper(
  File "/Users/naveed/opt/anaconda3/lib/python3.9/site-packages/google/api_core/retry/retry_base.py", line 221, in _retry_error_helper
    raise final_exc from source_exc
google.api_core.exceptions.RetryError: Timeout of 60.0s exceeded, last exception: 503 Getting metadata from plugin failed with error: ('invalid_grant: Invalid JWT Signature.', {'error': 'invalid_grant', 'error_description': 'Invalid JWT Signature.'})
